2024-05-19 13:12:10,074 - root - INFO - Logging setup complete.
2024-05-19 13:12:10,074 - root - INFO - Configuration loaded.
2024-05-19 13:12:10,390 - root - INFO - WebDriver setup complete.
2024-05-19 13:12:10,400 - root - INFO - Checking https://www.crownbio.com/resources for issues...
2024-05-19 13:12:12,290 - root - INFO - Checking https://www.crownbio.com/ for issues...
2024-05-19 13:12:12,293 - urllib3.connectionpool - WARNING - Retrying (Retry(total=2, connect=None, read=None, redirect=None, status=None)) after connection broken by 'NewConnectionError('<urllib3.connection.HTTPConnection object at 0x1079b4590>: Failed to establish a new connection: [Errno 61] Connection refused')': /session/2b6289d9751022d7b57900fa6375f093/url
2024-05-19 13:12:12,306 - urllib3.connectionpool - WARNING - Retrying (Retry(total=1, connect=None, read=None, redirect=None, status=None)) after connection broken by 'NewConnectionError('<urllib3.connection.HTTPConnection object at 0x1079b5110>: Failed to establish a new connection: [Errno 61] Connection refused')': /session/2b6289d9751022d7b57900fa6375f093/url
2024-05-19 13:12:12,311 - urllib3.connectionpool - WARNING - Retrying (Retry(total=0, connect=None, read=None, redirect=None, status=None)) after connection broken by 'NewConnectionError('<urllib3.connection.HTTPConnection object at 0x1079b5d90>: Failed to establish a new connection: [Errno 61] Connection refused')': /session/2b6289d9751022d7b57900fa6375f093/url
2024-05-19 13:12:12,322 - asyncio - ERROR - Task exception was never retrieved
future: <Task finished name='Task-2' coro=<tqdm_asyncio.gather.<locals>.wrap_awaitable() done, defined at /Users/joshua.jenkins/Projects/ReduceBounceRate/venv/lib/python3.11/site-packages/tqdm/asyncio.py:75> exception=ProtocolError('Connection aborted.', RemoteDisconnected('Remote end closed connection without response'))>
Traceback (most recent call last):
  File "/Users/joshua.jenkins/Projects/ReduceBounceRate/venv/lib/python3.11/site-packages/urllib3/connectionpool.py", line 793, in urlopen
    response = self._make_request(
               ^^^^^^^^^^^^^^^^^^^
  File "/Users/joshua.jenkins/Projects/ReduceBounceRate/venv/lib/python3.11/site-packages/urllib3/connectionpool.py", line 537, in _make_request
    response = conn.getresponse()
               ^^^^^^^^^^^^^^^^^^
  File "/Users/joshua.jenkins/Projects/ReduceBounceRate/venv/lib/python3.11/site-packages/urllib3/connection.py", line 466, in getresponse
    httplib_response = super().getresponse()
                       ^^^^^^^^^^^^^^^^^^^^^
  File "/opt/homebrew/Cellar/python@3.11/3.11.9/Frameworks/Python.framework/Versions/3.11/lib/python3.11/http/client.py", line 1395, in getresponse
    response.begin()
  File "/opt/homebrew/Cellar/python@3.11/3.11.9/Frameworks/Python.framework/Versions/3.11/lib/python3.11/http/client.py", line 325, in begin
    version, status, reason = self._read_status()
                              ^^^^^^^^^^^^^^^^^^^
  File "/opt/homebrew/Cellar/python@3.11/3.11.9/Frameworks/Python.framework/Versions/3.11/lib/python3.11/http/client.py", line 294, in _read_status
    raise RemoteDisconnected("Remote end closed connection without"
http.client.RemoteDisconnected: Remote end closed connection without response

During handling of the above exception, another exception occurred:

Traceback (most recent call last):
  File "/Users/joshua.jenkins/Projects/ReduceBounceRate/venv/lib/python3.11/site-packages/tqdm/asyncio.py", line 76, in wrap_awaitable
    return i, await f
              ^^^^^^^
  File "/Users/joshua.jenkins/Projects/ReduceBounceRate/main.py", line 53, in process_url
    driver.get(url)
  File "/Users/joshua.jenkins/Projects/ReduceBounceRate/venv/lib/python3.11/site-packages/selenium/webdriver/remote/webdriver.py", line 356, in get
    self.execute(Command.GET, {"url": url})
  File "/Users/joshua.jenkins/Projects/ReduceBounceRate/venv/lib/python3.11/site-packages/selenium/webdriver/remote/webdriver.py", line 345, in execute
    response = self.command_executor.execute(driver_command, params)
               ^^^^^^^^^^^^^^^^^^^^^^^^^^^^^^^^^^^^^^^^^^^^^^^^^^^^^
  File "/Users/joshua.jenkins/Projects/ReduceBounceRate/venv/lib/python3.11/site-packages/selenium/webdriver/remote/remote_connection.py", line 302, in execute
    return self._request(command_info[0], url, body=data)
           ^^^^^^^^^^^^^^^^^^^^^^^^^^^^^^^^^^^^^^^^^^^^^^
  File "/Users/joshua.jenkins/Projects/ReduceBounceRate/venv/lib/python3.11/site-packages/selenium/webdriver/remote/remote_connection.py", line 322, in _request
    response = self._conn.request(method, url, body=body, headers=headers)
               ^^^^^^^^^^^^^^^^^^^^^^^^^^^^^^^^^^^^^^^^^^^^^^^^^^^^^^^^^^^
  File "/Users/joshua.jenkins/Projects/ReduceBounceRate/venv/lib/python3.11/site-packages/urllib3/_request_methods.py", line 144, in request
    return self.request_encode_body(
           ^^^^^^^^^^^^^^^^^^^^^^^^^
  File "/Users/joshua.jenkins/Projects/ReduceBounceRate/venv/lib/python3.11/site-packages/urllib3/_request_methods.py", line 279, in request_encode_body
    return self.urlopen(method, url, **extra_kw)
           ^^^^^^^^^^^^^^^^^^^^^^^^^^^^^^^^^^^^^
  File "/Users/joshua.jenkins/Projects/ReduceBounceRate/venv/lib/python3.11/site-packages/urllib3/poolmanager.py", line 444, in urlopen
    response = conn.urlopen(method, u.request_uri, **kw)
               ^^^^^^^^^^^^^^^^^^^^^^^^^^^^^^^^^^^^^^^^^
  File "/Users/joshua.jenkins/Projects/ReduceBounceRate/venv/lib/python3.11/site-packages/urllib3/connectionpool.py", line 847, in urlopen
    retries = retries.increment(
              ^^^^^^^^^^^^^^^^^^
  File "/Users/joshua.jenkins/Projects/ReduceBounceRate/venv/lib/python3.11/site-packages/urllib3/util/retry.py", line 470, in increment
    raise reraise(type(error), error, _stacktrace)
          ^^^^^^^^^^^^^^^^^^^^^^^^^^^^^^^^^^^^^^^^
  File "/Users/joshua.jenkins/Projects/ReduceBounceRate/venv/lib/python3.11/site-packages/urllib3/util/util.py", line 38, in reraise
    raise value.with_traceback(tb)
  File "/Users/joshua.jenkins/Projects/ReduceBounceRate/venv/lib/python3.11/site-packages/urllib3/connectionpool.py", line 793, in urlopen
    response = self._make_request(
               ^^^^^^^^^^^^^^^^^^^
  File "/Users/joshua.jenkins/Projects/ReduceBounceRate/venv/lib/python3.11/site-packages/urllib3/connectionpool.py", line 537, in _make_request
    response = conn.getresponse()
               ^^^^^^^^^^^^^^^^^^
  File "/Users/joshua.jenkins/Projects/ReduceBounceRate/venv/lib/python3.11/site-packages/urllib3/connection.py", line 466, in getresponse
    httplib_response = super().getresponse()
                       ^^^^^^^^^^^^^^^^^^^^^
  File "/opt/homebrew/Cellar/python@3.11/3.11.9/Frameworks/Python.framework/Versions/3.11/lib/python3.11/http/client.py", line 1395, in getresponse
    response.begin()
  File "/opt/homebrew/Cellar/python@3.11/3.11.9/Frameworks/Python.framework/Versions/3.11/lib/python3.11/http/client.py", line 325, in begin
    version, status, reason = self._read_status()
                              ^^^^^^^^^^^^^^^^^^^
  File "/opt/homebrew/Cellar/python@3.11/3.11.9/Frameworks/Python.framework/Versions/3.11/lib/python3.11/http/client.py", line 294, in _read_status
    raise RemoteDisconnected("Remote end closed connection without"
urllib3.exceptions.ProtocolError: ('Connection aborted.', RemoteDisconnected('Remote end closed connection without response'))
2024-05-19 13:12:12,328 - asyncio - ERROR - Task exception was never retrieved
future: <Task finished name='Task-3' coro=<tqdm_asyncio.gather.<locals>.wrap_awaitable() done, defined at /Users/joshua.jenkins/Projects/ReduceBounceRate/venv/lib/python3.11/site-packages/tqdm/asyncio.py:75> exception=MaxRetryError("HTTPConnectionPool(host='localhost', port=59701): Max retries exceeded with url: /session/2b6289d9751022d7b57900fa6375f093/url (Caused by NewConnectionError('<urllib3.connection.HTTPConnection object at 0x1079b6a10>: Failed to establish a new connection: [Errno 61] Connection refused'))")>
Traceback (most recent call last):
  File "/Users/joshua.jenkins/Projects/ReduceBounceRate/venv/lib/python3.11/site-packages/urllib3/connection.py", line 198, in _new_conn
    sock = connection.create_connection(
           ^^^^^^^^^^^^^^^^^^^^^^^^^^^^^
  File "/Users/joshua.jenkins/Projects/ReduceBounceRate/venv/lib/python3.11/site-packages/urllib3/util/connection.py", line 85, in create_connection
    raise err
  File "/Users/joshua.jenkins/Projects/ReduceBounceRate/venv/lib/python3.11/site-packages/urllib3/util/connection.py", line 73, in create_connection
    sock.connect(sa)
ConnectionRefusedError: [Errno 61] Connection refused

The above exception was the direct cause of the following exception:

Traceback (most recent call last):
  File "/Users/joshua.jenkins/Projects/ReduceBounceRate/venv/lib/python3.11/site-packages/urllib3/connectionpool.py", line 793, in urlopen
    response = self._make_request(
               ^^^^^^^^^^^^^^^^^^^
  File "/Users/joshua.jenkins/Projects/ReduceBounceRate/venv/lib/python3.11/site-packages/urllib3/connectionpool.py", line 496, in _make_request
    conn.request(
  File "/Users/joshua.jenkins/Projects/ReduceBounceRate/venv/lib/python3.11/site-packages/urllib3/connection.py", line 400, in request
    self.endheaders()
  File "/opt/homebrew/Cellar/python@3.11/3.11.9/Frameworks/Python.framework/Versions/3.11/lib/python3.11/http/client.py", line 1298, in endheaders
    self._send_output(message_body, encode_chunked=encode_chunked)
  File "/opt/homebrew/Cellar/python@3.11/3.11.9/Frameworks/Python.framework/Versions/3.11/lib/python3.11/http/client.py", line 1058, in _send_output
    self.send(msg)
  File "/opt/homebrew/Cellar/python@3.11/3.11.9/Frameworks/Python.framework/Versions/3.11/lib/python3.11/http/client.py", line 996, in send
    self.connect()
  File "/Users/joshua.jenkins/Projects/ReduceBounceRate/venv/lib/python3.11/site-packages/urllib3/connection.py", line 238, in connect
    self.sock = self._new_conn()
                ^^^^^^^^^^^^^^^^
  File "/Users/joshua.jenkins/Projects/ReduceBounceRate/venv/lib/python3.11/site-packages/urllib3/connection.py", line 213, in _new_conn
    raise NewConnectionError(
urllib3.exceptions.NewConnectionError: <urllib3.connection.HTTPConnection object at 0x1079b6a10>: Failed to establish a new connection: [Errno 61] Connection refused

The above exception was the direct cause of the following exception:

Traceback (most recent call last):
  File "/Users/joshua.jenkins/Projects/ReduceBounceRate/venv/lib/python3.11/site-packages/tqdm/asyncio.py", line 76, in wrap_awaitable
    return i, await f
              ^^^^^^^
  File "/Users/joshua.jenkins/Projects/ReduceBounceRate/main.py", line 53, in process_url
    driver.get(url)
  File "/Users/joshua.jenkins/Projects/ReduceBounceRate/venv/lib/python3.11/site-packages/selenium/webdriver/remote/webdriver.py", line 356, in get
    self.execute(Command.GET, {"url": url})
  File "/Users/joshua.jenkins/Projects/ReduceBounceRate/venv/lib/python3.11/site-packages/selenium/webdriver/remote/webdriver.py", line 345, in execute
    response = self.command_executor.execute(driver_command, params)
               ^^^^^^^^^^^^^^^^^^^^^^^^^^^^^^^^^^^^^^^^^^^^^^^^^^^^^
  File "/Users/joshua.jenkins/Projects/ReduceBounceRate/venv/lib/python3.11/site-packages/selenium/webdriver/remote/remote_connection.py", line 302, in execute
    return self._request(command_info[0], url, body=data)
           ^^^^^^^^^^^^^^^^^^^^^^^^^^^^^^^^^^^^^^^^^^^^^^
  File "/Users/joshua.jenkins/Projects/ReduceBounceRate/venv/lib/python3.11/site-packages/selenium/webdriver/remote/remote_connection.py", line 322, in _request
    response = self._conn.request(method, url, body=body, headers=headers)
               ^^^^^^^^^^^^^^^^^^^^^^^^^^^^^^^^^^^^^^^^^^^^^^^^^^^^^^^^^^^
  File "/Users/joshua.jenkins/Projects/ReduceBounceRate/venv/lib/python3.11/site-packages/urllib3/_request_methods.py", line 144, in request
    return self.request_encode_body(
           ^^^^^^^^^^^^^^^^^^^^^^^^^
  File "/Users/joshua.jenkins/Projects/ReduceBounceRate/venv/lib/python3.11/site-packages/urllib3/_request_methods.py", line 279, in request_encode_body
    return self.urlopen(method, url, **extra_kw)
           ^^^^^^^^^^^^^^^^^^^^^^^^^^^^^^^^^^^^^
  File "/Users/joshua.jenkins/Projects/ReduceBounceRate/venv/lib/python3.11/site-packages/urllib3/poolmanager.py", line 444, in urlopen
    response = conn.urlopen(method, u.request_uri, **kw)
               ^^^^^^^^^^^^^^^^^^^^^^^^^^^^^^^^^^^^^^^^^
  File "/Users/joshua.jenkins/Projects/ReduceBounceRate/venv/lib/python3.11/site-packages/urllib3/connectionpool.py", line 877, in urlopen
    return self.urlopen(
           ^^^^^^^^^^^^^
  File "/Users/joshua.jenkins/Projects/ReduceBounceRate/venv/lib/python3.11/site-packages/urllib3/connectionpool.py", line 877, in urlopen
    return self.urlopen(
           ^^^^^^^^^^^^^
  File "/Users/joshua.jenkins/Projects/ReduceBounceRate/venv/lib/python3.11/site-packages/urllib3/connectionpool.py", line 877, in urlopen
    return self.urlopen(
           ^^^^^^^^^^^^^
  File "/Users/joshua.jenkins/Projects/ReduceBounceRate/venv/lib/python3.11/site-packages/urllib3/connectionpool.py", line 847, in urlopen
    retries = retries.increment(
              ^^^^^^^^^^^^^^^^^^
  File "/Users/joshua.jenkins/Projects/ReduceBounceRate/venv/lib/python3.11/site-packages/urllib3/util/retry.py", line 515, in increment
    raise MaxRetryError(_pool, url, reason) from reason  # type: ignore[arg-type]
    ^^^^^^^^^^^^^^^^^^^^^^^^^^^^^^^^^^^^^^^^^^^^^^^^^^^
urllib3.exceptions.MaxRetryError: HTTPConnectionPool(host='localhost', port=59701): Max retries exceeded with url: /session/2b6289d9751022d7b57900fa6375f093/url (Caused by NewConnectionError('<urllib3.connection.HTTPConnection object at 0x1079b6a10>: Failed to establish a new connection: [Errno 61] Connection refused'))
